<?xml version="1.0"?>
<robot xmlns:xacro="http://ros.org/wiki/xacro" name="pioneer3dx" >
  
  <!-- base_link -->
  <link name="base_link"/>
  
  <!-- Chassis -->
  <joint name="base_link_chassis_joint" type="fixed">
    <origin xyz="0 0 0" rpy="0 0 0"/>
    <parent link="base_link"/>
    <child link="chassis"/>
  </joint>
  <link name="chassis">
    <visual name="chassis_visual">
      <origin xyz="-0.045 0 0.148" rpy="0 0 0"/>
      <geometry name="pioneer_geom">
        <mesh filename="package://pioneer_description/urdf/multi_robot_base/meshes/p3dx_meshes/chassis.stl"/>
      </geometry>
      <material name="ChassisRed">
        <color rgba="0.851 0.0 0.0 1.0"/>
      </material>
    </visual>
    <collision>
      <origin xyz="-0.045 0 0.148" rpy="0 0 0"/>
      <geometry>
        <mesh filename="package://pioneer_description/urdf/multi_robot_base/meshes/p3dx_meshes/chassis.stl"/>
      </geometry>
    </collision>
    <xacro:box_inertial x="0.36" y="0.26"  z="0.18" mass="9.0" />
  </link>
  
  <!-- Top -->
  <joint name="chassis_top_joint" type="fixed">
    <origin xyz="-0.045 0 0.234" rpy="0 0 0"/>
    <parent link="chassis"/>
    <child link="top"/>
  </joint>
  <link name="top">
    <visual>
      <origin xyz="0 0 0" rpy="0 0 0"/>
      <geometry name="top_geom">
        <mesh filename="package://pioneer_description/urdf/multi_robot_base/meshes/p3dx_meshes/top.stl"/>
      </geometry>
      <material name="TopBlack">
        <color rgba="0.038 0.038 0.038 1.0"/>
      </material>
    </visual>
    <collision>
    <origin xyz="0.0 0 0.0" rpy="0 0 0"/>
      <geometry>
        <mesh filename="package://pioneer_description/urdf/multi_robot_base/meshes/p3dx_meshes/top.stl"/>
      </geometry>
    </collision>
    <xacro:box_inertial x="0.445" y="0.38"  z="0.01" mass="1.0" />
  </link>

  <!-- Front Sonar -->
  <joint name="base_link_sonar_joint" type="fixed">
    <origin xyz="0.109 0 0.209" rpy="0 0 0"/>
    <parent link="base_link"/>
    <child link="sonar"/>
  </joint>
  <link name="sonar">
    <inertial>
      <mass value="0.0001"/>
      <origin xyz="0 0 0"/>
      <inertia ixx="1" ixy="0" ixz="0" iyy="1" iyz="0" izz="1"/>
    </inertial>
    <visual name="front_sonar_vis">
      <origin xyz="0 0 0" rpy="0 0 0"/>
      <geometry name="pioneer_geom">
        <mesh filename="package://pioneer_description/urdf/multi_robot_base/meshes/p3dx_meshes/sonar.dae"/>
      </geometry>
      <material name="SonarYellow">
        <color rgba="0.715 0.583 0.210 1.0"/>
      </material>
    </visual>
    <collision>
      <origin xyz="0 0 0" rpy="0 0 0"/>
      <geometry>
        <box size="0.01 0.01 0.01"/>
      </geometry>
    </collision>
  </link>

  <!-- Battery -->
  <joint name="base_link_battery_joint" type="fixed">
    <origin xyz="-0.14 0 0.13" rpy="0 0 0"/>
    <parent link="base_link"/>
    <child link="battery"/>
  </joint>
  <link name="battery">
    <visual name="battery_visual">
      <origin xyz="0 0 0" rpy="0 0 0"/>
      <geometry name="battery_geometry">
        <box size="0.151 0.065 0.094"/>
      </geometry>
      <material name="battery_material">
        <color rgba="0.038 0.038 0.038 1.0"/>
      </material>
    </visual>
    <inertial>
      <mass value="2.5" />
      <origin xyz="0 0 0" />
      <inertia ixx="0.003520832" ixy="0.0" ixz="0.0"
        iyy="0.007604164" iyz="0.0"
        izz="0.004083332" />
    </inertial>
  </link>

  <!-- Hubcap -->
  <joint name="right_hub_joint" type="continuous">
    <origin xyz="0  0.15 0.09" rpy="0 0 0"/>
    <parent link="base_link"/>
    <child link="right_hub"/>
    <axis xyz="0 1 0"/>
  </joint>
  <link name="right_hub">
    <inertial>
      <mass value="0.01"/>
      <origin xyz="0 0 0"/>
      <inertia ixx="0.012411765597" ixy="0" ixz="0" iyy="0.015218160428" iyz="0" izz="0.011763977943"/>
    </inertial>
    <visual name="base_visual">
      <origin xyz="0 0 0" rpy="0 0 0"/>
      <geometry name="pioneer_geom">
        <mesh filename="package://pioneer_description/urdf/multi_robot_base/meshes/p3dx_meshes/right_hubcap.dae"/>
      </geometry>
      <material name="HubcapYellow">
        <color rgba="1.0 0.811 0.151 1.0"/>
      </material>
    </visual>
    <collision>
      <origin xyz="0 0 0" rpy="0 0 0"/>
      <geometry>
        <box size="0.01 0.01 0.01"/>
      </geometry>
    </collision>
  </link>

  <!-- Wheel -->
  <joint name="right_wheel_joint" type="fixed">
    <axis xyz="0 1 0"/>
    <origin xyz="0 0 0" rpy="0 0 0"/>
    <parent link="right_hub"/>
    <child link="right_wheel"/>
  </joint>
  <link name="right_wheel">
    <inertial>
      <mass value="0.5"/>
      <origin xyz="0 0 0"/>
      <inertia ixx="0.012411765597" ixy="0" ixz="0" iyy="0.015218160428" iyz="0" izz="0.011763977943"/>
    </inertial>
    <visual name="base_visual">
      <origin xyz="0 0 0" rpy="0 0 0"/>
      <geometry name="pioneer_geom">
        <mesh filename="package://pioneer_description/urdf/multi_robot_base/meshes/p3dx_meshes/right_wheel.dae"/>
      </geometry>
      <material name="WheelBlack">
        <color rgba="0.117 0.117 0.117 1"/>
      </material>
    </visual>
    <collision>
      <origin xyz="0 0 0" rpy="1.57 0 0"/>
      <geometry>
        <!--<mesh filename="${meshes}/${side}_wheel.stl"/>-->
        <cylinder radius="0.09" length="0.01"/>
      </geometry>
    </collision>
  </link>

  <!-- Hubcap-left -->
  <joint name="left_hub_joint" type="continuous">
    <origin xyz="0  -0.15 0.09" rpy="0 0 0"/>
    <parent link="base_link"/>
    <child link="left_hub"/>
    <axis xyz="0 1 0"/>
  </joint>
  <link name="left_hub">
    <inertial>
      <mass value="0.01"/>
      <origin xyz="0 0 0"/>
      <inertia ixx="0.012411765597" ixy="0" ixz="0" iyy="0.015218160428" iyz="0" izz="0.011763977943"/>
    </inertial>
    <visual name="base_visual">
      <origin xyz="0 0 0" rpy="0 0 0"/>
      <geometry name="pioneer_geom">
        <mesh filename="package://pioneer_description/urdf/multi_robot_base/meshes/p3dx_meshes/left_hubcap.dae"/>
      </geometry>
      <material name="HubcapYellow">
        <color rgba="1.0 0.811 0.151 1.0"/>
      </material>
    </visual>
    <collision>
      <origin xyz="0 0 0" rpy="0 0 0"/>
      <geometry>
        <box size="0.01 0.01 0.01"/>
      </geometry>
    </collision>
  </link>

  <!-- Wheel -->
  <joint name="left_wheel_joint" type="fixed">
    <axis xyz="0 1 0"/>
    <origin xyz="0 0 0" rpy="0 0 0"/>
    <parent link="left_hub"/>
    <child link="left_wheel"/>
  </joint>
  <link name="left_wheel">
    <inertial>
      <mass value="0.5"/>
      <origin xyz="0 0 0"/>
      <inertia ixx="0.012411765597" ixy="0" ixz="0" iyy="0.015218160428" iyz="0" izz="0.011763977943"/>
    </inertial>
    <visual name="base_visual">
      <origin xyz="0 0 0" rpy="0 0 0"/>
      <geometry name="pioneer_geom">
        <mesh filename="package://pioneer_description/urdf/multi_robot_base/meshes/p3dx_meshes/left_wheel.dae"/>
      </geometry>
      <material name="WheelBlack">
        <color rgba="0.117 0.117 0.117 1"/>
      </material>
    </visual>
    <collision>
      <origin xyz="0 0 0" rpy="1.57 0 0"/>
      <geometry>
        <!--<mesh filename="${meshes}/${side}_wheel.stl"/>-->
        <cylinder radius="0.09" length="0.01"/>
      </geometry>
    </collision>
  </link>

  <!-- Swivel -->
  <joint name="chassis_swivel_joint" type="continuous">
    <origin xyz="-0.185 0 0.055" rpy="0 0 0"/>
    <axis xyz="0 0 1"/>
    <anchor xyz="0 0 0"/>
    <limit effort="100" velocity="100" k_velocity="0"/>
    <joint_properties damping="0.0" friction="0.0"/>
    <parent link="base_link"/>
    <child link="swivel"/>
  </joint>
  <link name="swivel">
    <inertial>
      <mass value="0.1"/>
      <origin xyz="0 0 0"/>
      <inertia ixx="0.01" ixy="0" ixz="0" iyy="0.01" iyz="0" izz="0.01"/>
    </inertial>
    <visual name="base_visual">
      <origin xyz="0 0 0" rpy="0 0 0"/>
      <geometry name="pioneer_geom">
        <mesh filename="package://pioneer_description/urdf/multi_robot_base/meshes/p3dx_meshes/swivel.dae"/>
      </geometry>
      <material name="swivel">
        <color rgba="0.5 0.5 0.5 1"/>
      </material>
    </visual>
    <collision>
      <origin xyz="0 0 0" rpy="0 0 0"/>
      <geometry>
        <box size="0.01 0.01 0.01"/>
      </geometry>
    </collision>
  </link>
  <gazebo reference="swivel">
    <material value="Gazebo/Grey"/>
  </gazebo>
  
  <!-- Center Wheel -->
  <joint name="swivel_wheel_joint" type="continuous">
    <origin xyz="-0.017 0 -0.016" rpy="0 0 0"/>
    <axis xyz="0 1 0"/>
    <anchor xyz="0 0 0"/>
    <limit effort="100" velocity="100" k_velocity="0"/>
    <joint_properties damping="0.0" friction="0.0"/>
    <parent link="swivel"/>
    <child link="center_wheel"/>
  </joint>
  <link name="center_wheel">
    <inertial>
      <mass value="0.1"/>
      <origin xyz="0 0 0"/>
      <inertia ixx="0.012411765597" ixy="-0.000711733678" ixz="0.00050272983" iyy="0.015218160428" iyz="-0.000004273467" izz="0.011763977943"/>
    </inertial>
    <visual name="base_visual">
      <origin xyz="0 0 0" rpy="0 0 0"/>
      <geometry name="pioneer_geom">
        <mesh filename="package://pioneer_description/urdf/multi_robot_base/meshes/p3dx_meshes/center_wheel.dae"/>
      </geometry>
      <material name="WheelBlack">
        <color rgba="0.117 0.117 0.117 1"/>
      </material>
    </visual>
    <collision>
      <origin xyz="0 0 0" rpy="1.57 0 0"/>
      <geometry>
        <!--<mesh filename="${meshes}/center_wheel.stl"/>-->
        <cylinder radius="0.0375" length="0.01"/>
      </geometry>
    </collision>
  </link>
    
  <!-- Center Hubcap -->
  <joint name="wheel_hubcap_joint" type="fixed">
    <origin xyz="-0.0035 0 -0.001" rpy="0 0 0"/>
    <parent link="center_wheel"/>
    <child link="center_hubcap"/>
  </joint>
  <link name="center_hubcap">
    <inertial>
      <mass value="0.01"/>
      <origin xyz="0 0 0"/>
      <inertia ixx="0.012411765597" ixy="-0.000711733678" ixz="0.00050272983" iyy="0.015218160428" iyz="-0.000004273467" izz="0.011763977943"/>
    </inertial>
    <visual name="base_visual">
      <origin xyz="0 0 0" rpy="0 0 0"/>
      <geometry name="pioneer_geom">
        <mesh filename="package://pioneer_description/urdf/multi_robot_base/meshes/p3dx_meshes/center_hubcap.dae"/>
      </geometry>
      <material name="swivel">
        <color rgba="0.5 0.5 0.5 1"/>
      </material>
    </visual>
    <collision>
      <origin xyz="0 0 0" rpy="0 0 0"/>
      <geometry>
        <box size="0.01 0.01 0.01"/>
      </geometry>
    </collision>
  </link>   
</robot>
